<robot name="pi_robot">

<joint name="left_shoulder_forward_joint" type="revolute">
    <parent link="left_shoulder_link"/>
    <child link="left_shoulder_forward_link"/>
    <origin xyz="0 0.025 0" rpy="0 0 0"/>
    <limit lower="-1.57" upper="1.57" effort="10" velocity="3"/>
    <axis xyz="0 0 1"/>
    <dynamics damping="0.7"/>
</joint>

<transmission name="tran4">
    <type>transmission_interface/SimpleTransmission</type>
    <joint name="left_shoulder_forward_joint">
        <hardwareInterface>EffortJointInterface</hardwareInterface>
    </joint>
    <actuator name="motor4">
        <hardwareInterface>EffortJointInterface</hardwareInterface>
        <mechanicalReduction>1</mechanicalReduction>
    </actuator>
</transmission>